[2023-12-26T17:28:16.729+0000] {taskinstance.py:1957} INFO - Dependencies all met for dep_context=non-requeueable deps ti=<TaskInstance: batch_layer.batch_2 manual__2023-12-26T17:18:32.758200+00:00 [queued]>
[2023-12-26T17:28:16.733+0000] {taskinstance.py:1957} INFO - Dependencies all met for dep_context=requeueable deps ti=<TaskInstance: batch_layer.batch_2 manual__2023-12-26T17:18:32.758200+00:00 [queued]>
[2023-12-26T17:28:16.734+0000] {taskinstance.py:2171} INFO - Starting attempt 2 of 2
[2023-12-26T17:28:16.745+0000] {taskinstance.py:2192} INFO - Executing <Task(PythonOperator): batch_2> on 2023-12-26 17:18:32.758200+00:00
[2023-12-26T17:28:16.750+0000] {standard_task_runner.py:60} INFO - Started process 1216 to run task
[2023-12-26T17:28:16.754+0000] {standard_task_runner.py:87} INFO - Running: ['airflow', 'tasks', 'run', 'batch_layer', 'batch_2', 'manual__2023-12-26T17:18:32.758200+00:00', '--job-id', '36', '--raw', '--subdir', 'DAGS_FOLDER/BatchLayerDag.py', '--cfg-path', '/tmp/tmpiy1tn6f2']
[2023-12-26T17:28:16.756+0000] {standard_task_runner.py:88} INFO - Job 36: Subtask batch_2
[2023-12-26T17:28:16.784+0000] {task_command.py:423} INFO - Running <TaskInstance: batch_layer.batch_2 manual__2023-12-26T17:18:32.758200+00:00 [running]> on host ba237c0dfd1a
[2023-12-26T17:28:16.827+0000] {taskinstance.py:2481} INFO - Exporting env vars: AIRFLOW_CTX_DAG_EMAIL='airflow@example.com' AIRFLOW_CTX_DAG_OWNER='airflow' AIRFLOW_CTX_DAG_ID='batch_layer' AIRFLOW_CTX_TASK_ID='batch_2' AIRFLOW_CTX_EXECUTION_DATE='2023-12-26T17:18:32.758200+00:00' AIRFLOW_CTX_TRY_NUMBER='2' AIRFLOW_CTX_DAG_RUN_ID='manual__2023-12-26T17:18:32.758200+00:00'
[2023-12-26T17:28:16.829+0000] {taskinstance.py:2699} ERROR - Task failed with exception
Traceback (most recent call last):
  File "/home/airflow/.local/lib/python3.8/site-packages/airflow/models/taskinstance.py", line 433, in _execute_task
    result = execute_callable(context=context, **execute_callable_kwargs)
  File "/home/airflow/.local/lib/python3.8/site-packages/airflow/operators/python.py", line 199, in execute
    return_value = self.execute_callable()
  File "/home/airflow/.local/lib/python3.8/site-packages/airflow/operators/python.py", line 216, in execute_callable
    return self.python_callable(*self.op_args, **self.op_kwargs)
  File "/opt/airflow/dags/BatchLayerDag.py", line 30, in batch_2
    b2.batch_proc_2()
AttributeError: module 'batch_proc_2' has no attribute 'batch_proc_2'
[2023-12-26T17:28:16.835+0000] {taskinstance.py:1138} INFO - Marking task as FAILED. dag_id=batch_layer, task_id=batch_2, execution_date=20231226T171832, start_date=20231226T172816, end_date=20231226T172816
[2023-12-26T17:28:16.844+0000] {standard_task_runner.py:107} ERROR - Failed to execute job 36 for task batch_2 (module 'batch_proc_2' has no attribute 'batch_proc_2'; 1216)
[2023-12-26T17:28:16.885+0000] {local_task_job_runner.py:234} INFO - Task exited with return code 1
[2023-12-26T17:28:16.893+0000] {taskinstance.py:3281} INFO - 0 downstream tasks scheduled from follow-on schedule check
