[2023-12-22T22:08:30.733+0000] {taskinstance.py:1957} INFO - Dependencies all met for dep_context=non-requeueable deps ti=<TaskInstance: parquet.parquet scheduled__2023-12-21T00:00:00+00:00 [queued]>
[2023-12-22T22:08:30.738+0000] {taskinstance.py:1957} INFO - Dependencies all met for dep_context=requeueable deps ti=<TaskInstance: parquet.parquet scheduled__2023-12-21T00:00:00+00:00 [queued]>
[2023-12-22T22:08:30.739+0000] {taskinstance.py:2171} INFO - Starting attempt 2 of 2
[2023-12-22T22:08:30.751+0000] {taskinstance.py:2192} INFO - Executing <Task(PythonOperator): parquet> on 2023-12-21 00:00:00+00:00
[2023-12-22T22:08:30.756+0000] {standard_task_runner.py:60} INFO - Started process 288 to run task
[2023-12-22T22:08:30.759+0000] {standard_task_runner.py:87} INFO - Running: ['airflow', 'tasks', 'run', 'parquet', 'parquet', 'scheduled__2023-12-21T00:00:00+00:00', '--job-id', '9', '--raw', '--subdir', 'DAGS_FOLDER/parquet.py', '--cfg-path', '/tmp/tmpvku05miq']
[2023-12-22T22:08:30.762+0000] {standard_task_runner.py:88} INFO - Job 9: Subtask parquet
[2023-12-22T22:08:30.803+0000] {task_command.py:423} INFO - Running <TaskInstance: parquet.parquet scheduled__2023-12-21T00:00:00+00:00 [running]> on host f9bc372cbc19
[2023-12-22T22:08:30.855+0000] {taskinstance.py:2481} INFO - Exporting env vars: AIRFLOW_CTX_DAG_EMAIL='airflow@example.com' AIRFLOW_CTX_DAG_OWNER='airflow' AIRFLOW_CTX_DAG_ID='parquet' AIRFLOW_CTX_TASK_ID='parquet' AIRFLOW_CTX_EXECUTION_DATE='2023-12-21T00:00:00+00:00' AIRFLOW_CTX_TRY_NUMBER='2' AIRFLOW_CTX_DAG_RUN_ID='scheduled__2023-12-21T00:00:00+00:00'
[2023-12-22T22:08:30.858+0000] {taskinstance.py:2699} ERROR - Task failed with exception
Traceback (most recent call last):
  File "/home/airflow/.local/lib/python3.8/site-packages/airflow/models/taskinstance.py", line 433, in _execute_task
    result = execute_callable(context=context, **execute_callable_kwargs)
  File "/home/airflow/.local/lib/python3.8/site-packages/airflow/operators/python.py", line 199, in execute
    return_value = self.execute_callable()
  File "/home/airflow/.local/lib/python3.8/site-packages/airflow/operators/python.py", line 216, in execute_callable
    return self.python_callable(*self.op_args, **self.op_kwargs)
  File "/opt/airflow/dags/parquet.py", line 14, in parquet
    with open('/tmp/batchViews/df.parquet', 'x'):
FileNotFoundError: [Errno 2] No such file or directory: '/tmp/batchViews/df.parquet'
[2023-12-22T22:08:30.873+0000] {taskinstance.py:1138} INFO - Marking task as FAILED. dag_id=parquet, task_id=parquet, execution_date=20231221T000000, start_date=20231222T220830, end_date=20231222T220830
[2023-12-22T22:08:30.885+0000] {standard_task_runner.py:107} ERROR - Failed to execute job 9 for task parquet ([Errno 2] No such file or directory: '/tmp/batchViews/df.parquet'; 288)
[2023-12-22T22:08:30.892+0000] {local_task_job_runner.py:234} INFO - Task exited with return code 1
[2023-12-22T22:08:30.903+0000] {taskinstance.py:3281} INFO - 0 downstream tasks scheduled from follow-on schedule check
