[2023-12-23T14:44:15.276+0000] {taskinstance.py:1957} INFO - Dependencies all met for dep_context=non-requeueable deps ti=<TaskInstance: batch_layer.batch_1 manual__2023-12-23T14:36:53.822270+00:00 [queued]>
[2023-12-23T14:44:15.282+0000] {taskinstance.py:1957} INFO - Dependencies all met for dep_context=requeueable deps ti=<TaskInstance: batch_layer.batch_1 manual__2023-12-23T14:36:53.822270+00:00 [queued]>
[2023-12-23T14:44:15.283+0000] {taskinstance.py:2171} INFO - Starting attempt 1 of 2
[2023-12-23T14:44:15.297+0000] {taskinstance.py:2192} INFO - Executing <Task(PythonOperator): batch_1> on 2023-12-23 14:36:53.822270+00:00
[2023-12-23T14:44:15.303+0000] {standard_task_runner.py:60} INFO - Started process 3020 to run task
[2023-12-23T14:44:15.305+0000] {standard_task_runner.py:87} INFO - Running: ['airflow', 'tasks', 'run', 'batch_layer', 'batch_1', 'manual__2023-12-23T14:36:53.822270+00:00', '--job-id', '31', '--raw', '--subdir', 'DAGS_FOLDER/BatchLayerDag.py', '--cfg-path', '/tmp/tmps2d0n8j7']
[2023-12-23T14:44:15.308+0000] {standard_task_runner.py:88} INFO - Job 31: Subtask batch_1
[2023-12-23T14:44:15.338+0000] {task_command.py:423} INFO - Running <TaskInstance: batch_layer.batch_1 manual__2023-12-23T14:36:53.822270+00:00 [running]> on host 7de9f6b6c8f6
[2023-12-23T14:44:15.384+0000] {taskinstance.py:2481} INFO - Exporting env vars: AIRFLOW_CTX_DAG_EMAIL='airflow@example.com' AIRFLOW_CTX_DAG_OWNER='airflow' AIRFLOW_CTX_DAG_ID='batch_layer' AIRFLOW_CTX_TASK_ID='batch_1' AIRFLOW_CTX_EXECUTION_DATE='2023-12-23T14:36:53.822270+00:00' AIRFLOW_CTX_TRY_NUMBER='1' AIRFLOW_CTX_DAG_RUN_ID='manual__2023-12-23T14:36:53.822270+00:00'
[2023-12-23T14:44:15.437+0000] {hive.py:475} INFO - USE `finnhub_db`
[2023-12-23T14:44:15.485+0000] {hive.py:475} INFO - 
                SELECT *
                FROM finnhub_table
            
[2023-12-23T14:44:17.380+0000] {taskinstance.py:2699} ERROR - Task failed with exception
Traceback (most recent call last):
  File "/home/airflow/.local/lib/python3.8/site-packages/airflow/models/taskinstance.py", line 433, in _execute_task
    result = execute_callable(context=context, **execute_callable_kwargs)
  File "/home/airflow/.local/lib/python3.8/site-packages/airflow/operators/python.py", line 199, in execute
    return_value = self.execute_callable()
  File "/home/airflow/.local/lib/python3.8/site-packages/airflow/operators/python.py", line 216, in execute_callable
    return self.python_callable(*self.op_args, **self.op_kwargs)
  File "/opt/airflow/dags/BatchLayerDag.py", line 27, in batch_1
    b1.batch_proc_1()
  File "/opt/airflow/dags/batch_proc_1.py", line 34, in batch_proc_1
    df_filtered = df[df['crypto_pair'].notna()]
  File "/home/airflow/.local/lib/python3.8/site-packages/pandas/core/frame.py", line 3761, in __getitem__
    indexer = self.columns.get_loc(key)
  File "/home/airflow/.local/lib/python3.8/site-packages/pandas/core/indexes/range.py", line 349, in get_loc
    raise KeyError(key)
KeyError: 'crypto_pair'
[2023-12-23T14:44:17.398+0000] {taskinstance.py:1138} INFO - Marking task as UP_FOR_RETRY. dag_id=batch_layer, task_id=batch_1, execution_date=20231223T143653, start_date=20231223T144415, end_date=20231223T144417
[2023-12-23T14:44:17.411+0000] {standard_task_runner.py:107} ERROR - Failed to execute job 31 for task batch_1 ('crypto_pair'; 3020)
[2023-12-23T14:44:17.446+0000] {local_task_job_runner.py:234} INFO - Task exited with return code 1
[2023-12-23T14:44:17.457+0000] {taskinstance.py:3281} INFO - 0 downstream tasks scheduled from follow-on schedule check
