[2023-12-26T17:01:27.807+0000] {taskinstance.py:1957} INFO - Dependencies all met for dep_context=non-requeueable deps ti=<TaskInstance: batch_layer.batch_2 manual__2023-12-26T16:59:47.548435+00:00 [queued]>
[2023-12-26T17:01:27.812+0000] {taskinstance.py:1957} INFO - Dependencies all met for dep_context=requeueable deps ti=<TaskInstance: batch_layer.batch_2 manual__2023-12-26T16:59:47.548435+00:00 [queued]>
[2023-12-26T17:01:27.813+0000] {taskinstance.py:2171} INFO - Starting attempt 1 of 2
[2023-12-26T17:01:27.825+0000] {taskinstance.py:2192} INFO - Executing <Task(PythonOperator): batch_2> on 2023-12-26 16:59:47.548435+00:00
[2023-12-26T17:01:27.830+0000] {standard_task_runner.py:60} INFO - Started process 559 to run task
[2023-12-26T17:01:27.832+0000] {standard_task_runner.py:87} INFO - Running: ['airflow', 'tasks', 'run', 'batch_layer', 'batch_2', 'manual__2023-12-26T16:59:47.548435+00:00', '--job-id', '15', '--raw', '--subdir', 'DAGS_FOLDER/BatchLayerDag.py', '--cfg-path', '/tmp/tmpz2bub_vf']
[2023-12-26T17:01:27.834+0000] {standard_task_runner.py:88} INFO - Job 15: Subtask batch_2
[2023-12-26T17:01:27.858+0000] {task_command.py:423} INFO - Running <TaskInstance: batch_layer.batch_2 manual__2023-12-26T16:59:47.548435+00:00 [running]> on host ba237c0dfd1a
[2023-12-26T17:01:27.896+0000] {taskinstance.py:2481} INFO - Exporting env vars: AIRFLOW_CTX_DAG_EMAIL='airflow@example.com' AIRFLOW_CTX_DAG_OWNER='airflow' AIRFLOW_CTX_DAG_ID='batch_layer' AIRFLOW_CTX_TASK_ID='batch_2' AIRFLOW_CTX_EXECUTION_DATE='2023-12-26T16:59:47.548435+00:00' AIRFLOW_CTX_TRY_NUMBER='1' AIRFLOW_CTX_DAG_RUN_ID='manual__2023-12-26T16:59:47.548435+00:00'
[2023-12-26T17:01:27.940+0000] {hive.py:475} INFO - USE `finnhub_db`
[2023-12-26T17:01:27.971+0000] {hive.py:475} INFO - 
                SELECT *
                FROM finnhub_table
            
[2023-12-26T17:01:28.345+0000] {taskinstance.py:2699} ERROR - Task failed with exception
Traceback (most recent call last):
  File "/home/airflow/.local/lib/python3.8/site-packages/airflow/models/taskinstance.py", line 433, in _execute_task
    result = execute_callable(context=context, **execute_callable_kwargs)
  File "/home/airflow/.local/lib/python3.8/site-packages/airflow/operators/python.py", line 199, in execute
    return_value = self.execute_callable()
  File "/home/airflow/.local/lib/python3.8/site-packages/airflow/operators/python.py", line 216, in execute_callable
    return self.python_callable(*self.op_args, **self.op_kwargs)
  File "/opt/airflow/dags/BatchLayerDag.py", line 29, in batch_2
    b2.batch_proc_2()
  File "/opt/airflow/dags/batch_proc_2.py", line 51, in batch_proc_2
    result = df.groupby(['date', 's']).agg(max_price=('p', 'max'),min_price=('p','min')).reset_index()
  File "/home/airflow/.local/lib/python3.8/site-packages/pandas/core/frame.py", line 8252, in groupby
    return DataFrameGroupBy(
  File "/home/airflow/.local/lib/python3.8/site-packages/pandas/core/groupby/groupby.py", line 931, in __init__
    grouper, exclusions, obj = get_grouper(
  File "/home/airflow/.local/lib/python3.8/site-packages/pandas/core/groupby/grouper.py", line 985, in get_grouper
    raise KeyError(gpr)
KeyError: 's'
[2023-12-26T17:01:28.355+0000] {taskinstance.py:1138} INFO - Marking task as UP_FOR_RETRY. dag_id=batch_layer, task_id=batch_2, execution_date=20231226T165947, start_date=20231226T170127, end_date=20231226T170128
[2023-12-26T17:01:28.363+0000] {standard_task_runner.py:107} ERROR - Failed to execute job 15 for task batch_2 ('s'; 559)
[2023-12-26T17:01:28.407+0000] {local_task_job_runner.py:234} INFO - Task exited with return code 1
[2023-12-26T17:01:28.415+0000] {taskinstance.py:3281} INFO - 0 downstream tasks scheduled from follow-on schedule check
