[2023-12-22T23:22:21.213+0000] {taskinstance.py:1957} INFO - Dependencies all met for dep_context=non-requeueable deps ti=<TaskInstance: batch_layer.batch_0 scheduled__2023-12-21T00:00:00+00:00 [queued]>
[2023-12-22T23:22:21.219+0000] {taskinstance.py:1957} INFO - Dependencies all met for dep_context=requeueable deps ti=<TaskInstance: batch_layer.batch_0 scheduled__2023-12-21T00:00:00+00:00 [queued]>
[2023-12-22T23:22:21.220+0000] {taskinstance.py:2171} INFO - Starting attempt 1 of 2
[2023-12-22T23:22:21.234+0000] {taskinstance.py:2192} INFO - Executing <Task(PythonOperator): batch_0> on 2023-12-21 00:00:00+00:00
[2023-12-22T23:22:21.241+0000] {standard_task_runner.py:60} INFO - Started process 117 to run task
[2023-12-22T23:22:21.244+0000] {standard_task_runner.py:87} INFO - Running: ['airflow', 'tasks', 'run', 'batch_layer', 'batch_0', 'scheduled__2023-12-21T00:00:00+00:00', '--job-id', '3', '--raw', '--subdir', 'DAGS_FOLDER/BatchLayerDag.py', '--cfg-path', '/tmp/tmp0n_djokn']
[2023-12-22T23:22:21.247+0000] {standard_task_runner.py:88} INFO - Job 3: Subtask batch_0
[2023-12-22T23:22:21.283+0000] {task_command.py:423} INFO - Running <TaskInstance: batch_layer.batch_0 scheduled__2023-12-21T00:00:00+00:00 [running]> on host f948fe9399e2
[2023-12-22T23:22:21.353+0000] {taskinstance.py:2481} INFO - Exporting env vars: AIRFLOW_CTX_DAG_EMAIL='airflow@example.com' AIRFLOW_CTX_DAG_OWNER='airflow' AIRFLOW_CTX_DAG_ID='batch_layer' AIRFLOW_CTX_TASK_ID='batch_0' AIRFLOW_CTX_EXECUTION_DATE='2023-12-21T00:00:00+00:00' AIRFLOW_CTX_TRY_NUMBER='1' AIRFLOW_CTX_DAG_RUN_ID='scheduled__2023-12-21T00:00:00+00:00'
[2023-12-22T23:22:21.359+0000] {TSocket.py:142} INFO - Could not connect to ('172.21.0.14', 10000)
Traceback (most recent call last):
  File "/home/airflow/.local/lib/python3.8/site-packages/thrift/transport/TSocket.py", line 137, in open
    handle.connect(sockaddr)
ConnectionRefusedError: [Errno 111] Connection refused
[2023-12-22T23:22:21.362+0000] {TSocket.py:145} ERROR - Could not connect to any of [('172.21.0.14', 10000)]
[2023-12-22T23:22:21.363+0000] {taskinstance.py:2699} ERROR - Task failed with exception
Traceback (most recent call last):
  File "/home/airflow/.local/lib/python3.8/site-packages/airflow/models/taskinstance.py", line 433, in _execute_task
    result = execute_callable(context=context, **execute_callable_kwargs)
  File "/home/airflow/.local/lib/python3.8/site-packages/airflow/operators/python.py", line 199, in execute
    return_value = self.execute_callable()
  File "/home/airflow/.local/lib/python3.8/site-packages/airflow/operators/python.py", line 216, in execute_callable
    return self.python_callable(*self.op_args, **self.op_kwargs)
  File "/opt/airflow/dags/BatchLayerDag.py", line 21, in batch_0
    b0.batch_proc_0()
  File "/opt/airflow/dags/batch_proc_0.py", line 15, in batch_proc_0
    connection = hive.connect(host=hive_host, port=hive_port, database=hive_database)
  File "/home/airflow/.local/lib/python3.8/site-packages/pyhive/hive.py", line 143, in connect
    return Connection(*args, **kwargs)
  File "/home/airflow/.local/lib/python3.8/site-packages/pyhive/hive.py", line 269, in __init__
    self._transport.open()
  File "/home/airflow/.local/lib/python3.8/site-packages/thrift_sasl/__init__.py", line 74, in open
    self._trans.open()
  File "/home/airflow/.local/lib/python3.8/site-packages/thrift/transport/TSocket.py", line 146, in open
    raise TTransportException(type=TTransportException.NOT_OPEN, message=msg)
thrift.transport.TTransport.TTransportException: Could not connect to any of [('172.21.0.14', 10000)]
[2023-12-22T23:22:21.377+0000] {taskinstance.py:1138} INFO - Marking task as UP_FOR_RETRY. dag_id=batch_layer, task_id=batch_0, execution_date=20231221T000000, start_date=20231222T232221, end_date=20231222T232221
[2023-12-22T23:22:21.394+0000] {standard_task_runner.py:107} ERROR - Failed to execute job 3 for task batch_0 (Could not connect to any of [('172.21.0.14', 10000)]; 117)
[2023-12-22T23:22:21.419+0000] {local_task_job_runner.py:234} INFO - Task exited with return code 1
[2023-12-22T23:22:21.431+0000] {taskinstance.py:3281} INFO - 0 downstream tasks scheduled from follow-on schedule check
