[2023-12-26T17:20:46.359+0000] {taskinstance.py:1957} INFO - Dependencies all met for dep_context=non-requeueable deps ti=<TaskInstance: batch_layer.batch_3 manual__2023-12-26T17:18:32.758200+00:00 [queued]>
[2023-12-26T17:20:46.364+0000] {taskinstance.py:1957} INFO - Dependencies all met for dep_context=requeueable deps ti=<TaskInstance: batch_layer.batch_3 manual__2023-12-26T17:18:32.758200+00:00 [queued]>
[2023-12-26T17:20:46.365+0000] {taskinstance.py:2171} INFO - Starting attempt 1 of 2
[2023-12-26T17:20:46.377+0000] {taskinstance.py:2192} INFO - Executing <Task(PythonOperator): batch_3> on 2023-12-26 17:18:32.758200+00:00
[2023-12-26T17:20:46.383+0000] {standard_task_runner.py:60} INFO - Started process 1092 to run task
[2023-12-26T17:20:46.385+0000] {standard_task_runner.py:87} INFO - Running: ['airflow', 'tasks', 'run', 'batch_layer', 'batch_3', 'manual__2023-12-26T17:18:32.758200+00:00', '--job-id', '33', '--raw', '--subdir', 'DAGS_FOLDER/BatchLayerDag.py', '--cfg-path', '/tmp/tmpvmkyh2np']
[2023-12-26T17:20:46.387+0000] {standard_task_runner.py:88} INFO - Job 33: Subtask batch_3
[2023-12-26T17:20:46.412+0000] {task_command.py:423} INFO - Running <TaskInstance: batch_layer.batch_3 manual__2023-12-26T17:18:32.758200+00:00 [running]> on host ba237c0dfd1a
[2023-12-26T17:20:46.454+0000] {taskinstance.py:2481} INFO - Exporting env vars: AIRFLOW_CTX_DAG_EMAIL='airflow@example.com' AIRFLOW_CTX_DAG_OWNER='airflow' AIRFLOW_CTX_DAG_ID='batch_layer' AIRFLOW_CTX_TASK_ID='batch_3' AIRFLOW_CTX_EXECUTION_DATE='2023-12-26T17:18:32.758200+00:00' AIRFLOW_CTX_TRY_NUMBER='1' AIRFLOW_CTX_DAG_RUN_ID='manual__2023-12-26T17:18:32.758200+00:00'
[2023-12-26T17:20:46.455+0000] {taskinstance.py:2699} ERROR - Task failed with exception
Traceback (most recent call last):
  File "/home/airflow/.local/lib/python3.8/site-packages/airflow/models/taskinstance.py", line 433, in _execute_task
    result = execute_callable(context=context, **execute_callable_kwargs)
  File "/home/airflow/.local/lib/python3.8/site-packages/airflow/operators/python.py", line 199, in execute
    return_value = self.execute_callable()
  File "/home/airflow/.local/lib/python3.8/site-packages/airflow/operators/python.py", line 216, in execute_callable
    return self.python_callable(*self.op_args, **self.op_kwargs)
  File "/opt/airflow/dags/BatchLayerDag.py", line 32, in batch_3
    b3.batch_proc_3()
AttributeError: module 'batch_proc_3' has no attribute 'batch_proc_3'
[2023-12-26T17:20:46.461+0000] {taskinstance.py:1138} INFO - Marking task as UP_FOR_RETRY. dag_id=batch_layer, task_id=batch_3, execution_date=20231226T171832, start_date=20231226T172046, end_date=20231226T172046
[2023-12-26T17:20:46.468+0000] {standard_task_runner.py:107} ERROR - Failed to execute job 33 for task batch_3 (module 'batch_proc_3' has no attribute 'batch_proc_3'; 1092)
[2023-12-26T17:20:46.477+0000] {local_task_job_runner.py:234} INFO - Task exited with return code 1
[2023-12-26T17:20:46.486+0000] {taskinstance.py:3281} INFO - 0 downstream tasks scheduled from follow-on schedule check
