[2023-12-26T17:28:19.318+0000] {taskinstance.py:1957} INFO - Dependencies all met for dep_context=non-requeueable deps ti=<TaskInstance: batch_layer.batch_3 manual__2023-12-26T17:18:32.758200+00:00 [queued]>
[2023-12-26T17:28:19.322+0000] {taskinstance.py:1957} INFO - Dependencies all met for dep_context=requeueable deps ti=<TaskInstance: batch_layer.batch_3 manual__2023-12-26T17:18:32.758200+00:00 [queued]>
[2023-12-26T17:28:19.323+0000] {taskinstance.py:2171} INFO - Starting attempt 2 of 2
[2023-12-26T17:28:19.334+0000] {taskinstance.py:2192} INFO - Executing <Task(PythonOperator): batch_3> on 2023-12-26 17:18:32.758200+00:00
[2023-12-26T17:28:19.338+0000] {standard_task_runner.py:60} INFO - Started process 1235 to run task
[2023-12-26T17:28:19.341+0000] {standard_task_runner.py:87} INFO - Running: ['airflow', 'tasks', 'run', 'batch_layer', 'batch_3', 'manual__2023-12-26T17:18:32.758200+00:00', '--job-id', '37', '--raw', '--subdir', 'DAGS_FOLDER/BatchLayerDag.py', '--cfg-path', '/tmp/tmpqnaevei1']
[2023-12-26T17:28:19.343+0000] {standard_task_runner.py:88} INFO - Job 37: Subtask batch_3
[2023-12-26T17:28:19.371+0000] {task_command.py:423} INFO - Running <TaskInstance: batch_layer.batch_3 manual__2023-12-26T17:18:32.758200+00:00 [running]> on host ba237c0dfd1a
[2023-12-26T17:28:19.435+0000] {taskinstance.py:2481} INFO - Exporting env vars: AIRFLOW_CTX_DAG_EMAIL='airflow@example.com' AIRFLOW_CTX_DAG_OWNER='airflow' AIRFLOW_CTX_DAG_ID='batch_layer' AIRFLOW_CTX_TASK_ID='batch_3' AIRFLOW_CTX_EXECUTION_DATE='2023-12-26T17:18:32.758200+00:00' AIRFLOW_CTX_TRY_NUMBER='2' AIRFLOW_CTX_DAG_RUN_ID='manual__2023-12-26T17:18:32.758200+00:00'
[2023-12-26T17:28:19.437+0000] {taskinstance.py:2699} ERROR - Task failed with exception
Traceback (most recent call last):
  File "/home/airflow/.local/lib/python3.8/site-packages/airflow/models/taskinstance.py", line 433, in _execute_task
    result = execute_callable(context=context, **execute_callable_kwargs)
  File "/home/airflow/.local/lib/python3.8/site-packages/airflow/operators/python.py", line 199, in execute
    return_value = self.execute_callable()
  File "/home/airflow/.local/lib/python3.8/site-packages/airflow/operators/python.py", line 216, in execute_callable
    return self.python_callable(*self.op_args, **self.op_kwargs)
  File "/opt/airflow/dags/BatchLayerDag.py", line 32, in batch_3
    b3.batch_proc_3()
AttributeError: module 'batch_proc_3' has no attribute 'batch_proc_3'
[2023-12-26T17:28:19.443+0000] {taskinstance.py:1138} INFO - Marking task as FAILED. dag_id=batch_layer, task_id=batch_3, execution_date=20231226T171832, start_date=20231226T172819, end_date=20231226T172819
[2023-12-26T17:28:19.452+0000] {standard_task_runner.py:107} ERROR - Failed to execute job 37 for task batch_3 (module 'batch_proc_3' has no attribute 'batch_proc_3'; 1235)
[2023-12-26T17:28:19.473+0000] {local_task_job_runner.py:234} INFO - Task exited with return code 1
[2023-12-26T17:28:19.482+0000] {taskinstance.py:3281} INFO - 0 downstream tasks scheduled from follow-on schedule check
