[2023-12-23T11:54:23.178+0000] {taskinstance.py:1957} INFO - Dependencies all met for dep_context=non-requeueable deps ti=<TaskInstance: batch_layer.batch_0 manual__2023-12-23T11:43:21.168415+00:00 [queued]>
[2023-12-23T11:54:23.182+0000] {taskinstance.py:1957} INFO - Dependencies all met for dep_context=requeueable deps ti=<TaskInstance: batch_layer.batch_0 manual__2023-12-23T11:43:21.168415+00:00 [queued]>
[2023-12-23T11:54:23.183+0000] {taskinstance.py:2171} INFO - Starting attempt 2 of 2
[2023-12-23T11:54:23.194+0000] {taskinstance.py:2192} INFO - Executing <Task(PythonOperator): batch_0> on 2023-12-23 11:43:21.168415+00:00
[2023-12-23T11:54:23.198+0000] {standard_task_runner.py:60} INFO - Started process 751 to run task
[2023-12-23T11:54:23.205+0000] {standard_task_runner.py:87} INFO - Running: ['airflow', 'tasks', 'run', 'batch_layer', 'batch_0', 'manual__2023-12-23T11:43:21.168415+00:00', '--job-id', '13', '--raw', '--subdir', 'DAGS_FOLDER/BatchLayerDag.py', '--cfg-path', '/tmp/tmpssumi8hq']
[2023-12-23T11:54:23.207+0000] {standard_task_runner.py:88} INFO - Job 13: Subtask batch_0
[2023-12-23T11:54:23.234+0000] {task_command.py:423} INFO - Running <TaskInstance: batch_layer.batch_0 manual__2023-12-23T11:43:21.168415+00:00 [running]> on host 7de9f6b6c8f6
[2023-12-23T11:54:23.281+0000] {taskinstance.py:2481} INFO - Exporting env vars: AIRFLOW_CTX_DAG_EMAIL='airflow@example.com' AIRFLOW_CTX_DAG_OWNER='airflow' AIRFLOW_CTX_DAG_ID='batch_layer' AIRFLOW_CTX_TASK_ID='batch_0' AIRFLOW_CTX_EXECUTION_DATE='2023-12-23T11:43:21.168415+00:00' AIRFLOW_CTX_TRY_NUMBER='2' AIRFLOW_CTX_DAG_RUN_ID='manual__2023-12-23T11:43:21.168415+00:00'
[2023-12-23T11:54:23.282+0000] {taskinstance.py:2699} ERROR - Task failed with exception
Traceback (most recent call last):
  File "/home/airflow/.local/lib/python3.8/site-packages/airflow/models/taskinstance.py", line 433, in _execute_task
    result = execute_callable(context=context, **execute_callable_kwargs)
  File "/home/airflow/.local/lib/python3.8/site-packages/airflow/operators/python.py", line 199, in execute
    return_value = self.execute_callable()
  File "/home/airflow/.local/lib/python3.8/site-packages/airflow/operators/python.py", line 216, in execute_callable
    return self.python_callable(*self.op_args, **self.op_kwargs)
  File "/opt/airflow/dags/BatchLayerDag.py", line 21, in batch_0
    b0.batch_proc_0()
AttributeError: module 'batch_proc_0' has no attribute 'batch_proc_0'
[2023-12-23T11:54:23.289+0000] {taskinstance.py:1138} INFO - Marking task as FAILED. dag_id=batch_layer, task_id=batch_0, execution_date=20231223T114321, start_date=20231223T115423, end_date=20231223T115423
[2023-12-23T11:54:23.328+0000] {standard_task_runner.py:107} ERROR - Failed to execute job 13 for task batch_0 (module 'batch_proc_0' has no attribute 'batch_proc_0'; 751)
[2023-12-23T11:54:23.334+0000] {local_task_job_runner.py:234} INFO - Task exited with return code 1
[2023-12-23T11:54:23.342+0000] {taskinstance.py:3281} INFO - 0 downstream tasks scheduled from follow-on schedule check
