[2023-12-26T17:30:57.594+0000] {taskinstance.py:1957} INFO - Dependencies all met for dep_context=non-requeueable deps ti=<TaskInstance: batch_layer.batch_3 manual__2023-12-26T17:29:22.301639+00:00 [queued]>
[2023-12-26T17:30:57.598+0000] {taskinstance.py:1957} INFO - Dependencies all met for dep_context=requeueable deps ti=<TaskInstance: batch_layer.batch_3 manual__2023-12-26T17:29:22.301639+00:00 [queued]>
[2023-12-26T17:30:57.599+0000] {taskinstance.py:2171} INFO - Starting attempt 1 of 2
[2023-12-26T17:30:57.609+0000] {taskinstance.py:2192} INFO - Executing <Task(PythonOperator): batch_3> on 2023-12-26 17:29:22.301639+00:00
[2023-12-26T17:30:57.614+0000] {standard_task_runner.py:60} INFO - Started process 1455 to run task
[2023-12-26T17:30:57.616+0000] {standard_task_runner.py:87} INFO - Running: ['airflow', 'tasks', 'run', 'batch_layer', 'batch_3', 'manual__2023-12-26T17:29:22.301639+00:00', '--job-id', '46', '--raw', '--subdir', 'DAGS_FOLDER/BatchLayerDag.py', '--cfg-path', '/tmp/tmpimy2q3kj']
[2023-12-26T17:30:57.618+0000] {standard_task_runner.py:88} INFO - Job 46: Subtask batch_3
[2023-12-26T17:30:57.640+0000] {task_command.py:423} INFO - Running <TaskInstance: batch_layer.batch_3 manual__2023-12-26T17:29:22.301639+00:00 [running]> on host ba237c0dfd1a
[2023-12-26T17:30:57.680+0000] {taskinstance.py:2481} INFO - Exporting env vars: AIRFLOW_CTX_DAG_EMAIL='airflow@example.com' AIRFLOW_CTX_DAG_OWNER='airflow' AIRFLOW_CTX_DAG_ID='batch_layer' AIRFLOW_CTX_TASK_ID='batch_3' AIRFLOW_CTX_EXECUTION_DATE='2023-12-26T17:29:22.301639+00:00' AIRFLOW_CTX_TRY_NUMBER='1' AIRFLOW_CTX_DAG_RUN_ID='manual__2023-12-26T17:29:22.301639+00:00'
[2023-12-26T17:30:57.719+0000] {hive.py:475} INFO - USE `finnhub_db`
[2023-12-26T17:30:57.754+0000] {hive.py:475} INFO - 
                SELECT *
                FROM finnhub_table
            
[2023-12-26T17:30:57.971+0000] {logging_mixin.py:188} INFO -          date        s  max_price  min_price
0  2023-12-25  BTCUSDT   43694.01  43363.340
1  2023-12-25  ETHUSDT    2295.24   2268.240
2  2023-12-26  BTCUSDT   42749.48  42325.390
3  2023-12-26  ETHUSDT    2246.27   2224.050
4  2023-12-26     None     375.53    153.405
[2023-12-26T17:30:57.974+0000] {logging_mixin.py:188} INFO - File '/tmp/batchViews/parquet_output_3.parquet' created successfully.
[2023-12-26T17:30:57.975+0000] {taskinstance.py:2699} ERROR - Task failed with exception
Traceback (most recent call last):
  File "/home/airflow/.local/lib/python3.8/site-packages/pandas/core/indexes/base.py", line 3653, in get_loc
    return self._engine.get_loc(casted_key)
  File "pandas/_libs/index.pyx", line 147, in pandas._libs.index.IndexEngine.get_loc
  File "pandas/_libs/index.pyx", line 176, in pandas._libs.index.IndexEngine.get_loc
  File "pandas/_libs/hashtable_class_helper.pxi", line 7080, in pandas._libs.hashtable.PyObjectHashTable.get_item
  File "pandas/_libs/hashtable_class_helper.pxi", line 7088, in pandas._libs.hashtable.PyObjectHashTable.get_item
KeyError: 't'

The above exception was the direct cause of the following exception:

Traceback (most recent call last):
  File "/home/airflow/.local/lib/python3.8/site-packages/airflow/models/taskinstance.py", line 433, in _execute_task
    result = execute_callable(context=context, **execute_callable_kwargs)
  File "/home/airflow/.local/lib/python3.8/site-packages/airflow/operators/python.py", line 199, in execute
    return_value = self.execute_callable()
  File "/home/airflow/.local/lib/python3.8/site-packages/airflow/operators/python.py", line 216, in execute_callable
    return self.python_callable(*self.op_args, **self.op_kwargs)
  File "/opt/airflow/dags/BatchLayerDag.py", line 32, in batch_3
    b3.batch_proc_3()
  File "/opt/airflow/dags/batch_proc_3.py", line 61, in batch_proc_3
    result['t'] = result['t'].dt.floor('us')
  File "/home/airflow/.local/lib/python3.8/site-packages/pandas/core/frame.py", line 3761, in __getitem__
    indexer = self.columns.get_loc(key)
  File "/home/airflow/.local/lib/python3.8/site-packages/pandas/core/indexes/base.py", line 3655, in get_loc
    raise KeyError(key) from err
KeyError: 't'
[2023-12-26T17:30:57.983+0000] {taskinstance.py:1138} INFO - Marking task as UP_FOR_RETRY. dag_id=batch_layer, task_id=batch_3, execution_date=20231226T172922, start_date=20231226T173057, end_date=20231226T173057
[2023-12-26T17:30:57.991+0000] {standard_task_runner.py:107} ERROR - Failed to execute job 46 for task batch_3 ('t'; 1455)
[2023-12-26T17:30:58.030+0000] {local_task_job_runner.py:234} INFO - Task exited with return code 1
[2023-12-26T17:30:58.038+0000] {taskinstance.py:3281} INFO - 0 downstream tasks scheduled from follow-on schedule check
